# Promise.all() II

```js
const promise1 = Promise.resolve(1);
const promise2 = Promise.resolve(2);
const promise3 = Promise.resolve(3);
const promise4 = Promise.reject(4);

const promiseAll = async () => {
  const group1 = await Promise.all([promise1, promise2]);
  const group2 = await Promise.all([promise3, promise4]);
  return [group1, group2];
};

promiseAll().then(console.log).catch(console.log);
```

[Problem Link](https://bigfrontend.dev/quiz/Promise-all-II

## Solution

```
4
```

## Explanation

[Promise.all()](https://developer.mozilla.org/en-US/docs/Web/JavaScript/Reference/Global_Objects/Promise/all) takes an iterable of promises as input and returns a single Promise. This returned promise fulfills when all of the input's promises fulfill, with an array of the fulfillment values. It `rejects` when any of the input's promises rejects, with this first rejection reason.

So when promiseAll(which is just a wrapper function) is invoked, out of the four promises, `promise4` rejects with value 4 . So the result is no longer available, and an error is thrown which gets captured in the `catch` and logs 4 to the console.

Thus

```js
const promise1 = Promise.resolve(1);
const promise2 = Promise.resolve(2);
const promise3 = Promise.resolve(3);
const promise4 = Promise.reject(4);

const promiseAll = async () => {
  const group1 = await Promise.all([promise1, promise2]);
  const group2 = await Promise.all([promise3, promise4]);
  return [group1, group2];
};

promiseAll().then(console.log).catch(console.log);

// 4
```
